Workbook

Sheet Lista completa
A3: Juego | B3: Sección | C3: Estado en la R36S | D3: Cómo se juega | E3: Qué necesitás | F3: Controles | G3: Notas | H3: Base del dato
A4: Final Fantasy VII | B4: Tus juegos | C4: Funciona | D4: Nuestro port (menú Ports, PCSX-ReARMed) | E4: Tus 3 discos (.bin completos) | F4: Control | G4: Ya funciona en tu R36S | H4: Probado en tu consola
A5: Baldur's Gate + Tales of the Sword Coast | B5: Tus juegos | C5: Funciona | D5: PortMaster (GemRB) | E5: Tus archivos (versión original) | F5: Stick como mouse | G5: 640×480, igual que la pantalla. Enhanced Edition: experimental | H5: Catálogo PortMaster
A6: Baldur's Gate II + Throne of Bhaal | B6: Tus juegos | C6: Funciona | D6: PortMaster (GemRB) | E6: Tus archivos (versión original) | F6: Stick como mouse | G6: 640×480, igual que la pantalla. Enhanced Edition: experimental | H6: Catálogo PortMaster
A7: Monkey Island 1 (The Secret of Monkey Island) | B7: Tus juegos | C7: Funciona | D7: ScummVM (ArkOS) | E7: Tus archivos originales | F7: Stick como mouse | G7: Aventura de apuntar y clic | H7: Estimación
A8: Monkey Island 2: LeChuck's Revenge | B8: Tus juegos | C8: Funciona | D8: ScummVM (ArkOS) | E8: Tus archivos originales | F8: Stick como mouse | G8: Aventura de apuntar y clic | H8: Estimación
A9: The Curse of Monkey Island (3) | B9: Tus juegos | C9: Funciona | D9: ScummVM (ArkOS) | E9: Tus archivos originales | F9: Stick como mouse | G9: Es de 640×480 | H9: Estimación
A10: Deltarune | B10: Tus juegos | C10: Funciona | D10: PortMaster | E10: Tus archivos (capítulos 1 a 4) | F10: Control | H10: Catálogo PortMaster
A11: Celeste | B11: Tus juegos | C11: Funciona | D11: PortMaster | E11: Versión sin DRM (itch.io o Epic) | F11: Control | G11: Celeste Classic y Celeste 64: gratis | H11: Catálogo PortMaster
A12: Aliens versus Predator (1999) | B12: Tus juegos | C12: Funciona | D12: PortMaster | E12: Tus archivos de PC (1999) | F12: Control | H12: Catálogo PortMaster
A13: Quake | B13: Tus juegos | C13: Funciona | D13: PortMaster | E13: Gratis (demo) o tus .pak | F13: Control | H13: Catálogo PortMaster
A14: Quake II | B14: Tus juegos | C14: Funciona | D14: PortMaster | E14: Tus .pak (+ expansiones) | F14: Control | H14: Catálogo PortMaster
A15: Half-Life (+ Blue Shift y Opposing Force) | B15: Tus juegos | C15: Funciona | D15: PortMaster (Xash3D) | E15: Carpeta valve de Steam | F15: Control | H15: Catálogo PortMaster
A16: Balatro | B16: Tus juegos | C16: Funciona | D16: PortMaster | E16: Balatro.exe (Steam) o Balatro.love (Mac) | F16: Control | H16: Catálogo PortMaster
A17: Brogue | B17: Tus juegos | C17: Funciona | D17: PortMaster | E17: Gratis | F17: Control | H17: Catálogo PortMaster
A18: FAITH: The Unholy Trinity | B18: Tus juegos | C18: Funciona | D18: PortMaster | E18: Tus archivos (Steam o GOG) | F18: Control | H18: Catálogo PortMaster
A19: The Elder Scrolls: Arena | B19: Tus juegos | C19: Funciona | D19: Emulador de DOS (ArkOS) | E19: Gratis (lo regaló Bethesda) | F19: Teclas mapeadas al control | G19: El motor libre OpenTESArena todavía está incompleto | H19: Estimación
A20: Might and Magic I a V | B20: Tus juegos | C20: Funciona | D20: Emulador de DOS (ArkOS) | E20: Tus archivos (GOG) | F20: Teclas mapeadas al control | G20: RPG de DOS | H20: Estimación
A21: Might and Magic VII | B21: Tus juegos | C21: Funciona | D21: PortMaster (OpenEnroth) | E21: Tus archivos (GOG) | F21: Dos sticks | H21: Catálogo PortMaster
A22: Heroes of Might and Magic II | B22: Tus juegos | C22: Funciona | D22: PortMaster (fheroes2) | E22: Tus archivos | F22: Stick como mouse | G22: Por turnos: cómodo con stick | H22: Catálogo PortMaster
A23: Heroes of Might and Magic III | B23: Tus juegos | C23: Funciona | D23: PortMaster (VCMI) | E23: Tus archivos | F23: Stick como mouse | G23: Por turnos: cómodo con stick | H23: Catálogo PortMaster
A24: Civilization (1991) | B24: Tus juegos | C24: Funciona | D24: Emulador de DOS (ArkOS) | E24: Tus archivos | F24: Stick como mouse | G24: Por turnos | H24: Estimación
A25: FreeCiv (estilo Civilization II) | B25: Tus juegos | C25: Funciona | D25: PortMaster | E25: Gratis | F25: Stick como mouse | G25: Por turnos | H25: Catálogo PortMaster
A26: Unciv (remake de Civilization V) | B26: Tus juegos | C26: Funciona | D26: PortMaster | E26: Gratis | F26: Stick como mouse | G26: Por turnos | H26: Catálogo PortMaster
A27: FreeCol (estilo Colonization) | B27: Tus juegos | C27: Funciona | D27: PortMaster | E27: Gratis | F27: Stick como mouse | G27: Por turnos | H27: Catálogo PortMaster
A28: ClassiCube (Minecraft Classic) | B28: Tus juegos | C28: Funciona | D28: PortMaster | E28: Gratis | F28: Control | G28: La alternativa liviana a Minecraft | H28: Catálogo PortMaster
A29: Quake III Arena | B29: Tus juegos | C29: Con reservas | D29: PortMaster | E29: Tus .pak y tu clave de CD | F29: Control | G29: El más exigente de los tres Quake | H29: Catálogo PortMaster
A30: Stardew Valley | B30: Tus juegos | C30: Con reservas | D30: PortMaster | E30: Tus archivos (Steam o GOG) | F30: Control | G30: Puede ir pesado con 1 GB de RAM | H30: Catálogo PortMaster
A31: Morrowind | B31: Tus juegos | C31: Con reservas | D31: PortMaster (OpenMW) | E31: Tus archivos (PC o GOG) | F31: Dos sticks | G31: Esperá pocos cuadros por segundo | H31: Catálogo PortMaster
A32: The Elder Scrolls II: Daggerfall | B32: Tus juegos | C32: Con reservas | D32: Emulador de DOS (ArkOS) | E32: Gratis (lo regaló Bethesda) | F32: Teclas mapeadas al control | G32: Pedía una Pentium: probablemente lento. Daggerfall Unity no entra | H32: Estimación
A33: Minecraft: Java Edition | B33: Tus juegos | C33: Con reservas | D33: PortMaster | E33: Tu copia del juego | F33: Dos sticks | G33: Con 1 GB de RAM, muy difícil | H33: Catálogo PortMaster
... A57: Return to Monkey Island | B57: Tus juegos | C57: No (streaming) | D57: Moonlight desde tu PC | E57: — | F57: — | G57: Motor moderno sin port | H57: Estimación
A58: Diablo (DevilutionX) | B58: Recomendados (PortMaster) | C58: Funciona | D58: PortMaster | E58: Listo para usar (demo); completo con tus archivos | F58: Control | H58: Catálogo PortMaster
A59: Doom | B59: Recomendados (PortMaster) | C59: Funciona | D59: PortMaster | E59: Gratis o tus archivos | F59: Control | H59: Catálogo PortMaster
A60: Duke Nukem 3D | B60: Recomendados (PortMaster) | C60: Funciona | D60: PortMaster | E60: Tus archivos | F60: Control | H60: Catálogo PortMaster
A61: Tomb Raider I | B61: Recomendados (PortMaster) | C61: Funciona | D61: PortMaster | E61: Tus archivos | F61: Control | H61: Catálogo PortMaster
A62: Sonic Mania | B62: Recomendados (PortMaster) | C62: Funciona | D62: PortMaster | E62: Tus archivos | F62: Control | H62: Catálogo PortMaster
A63: Sonic 1, 2, CD y 3 A.I.R. | B63: Recomendados (PortMaster) | C63: Funciona | D63: PortMaster | E63: Tus archivos | F63: Control | H63: Catálogo PortMaster
A64: Star Fox 64 (Project Starship) | B64: Recomendados (PortMaster) | C64: Funciona | D64: PortMaster | E64: Tu ROM | F64: Control | H64: Catálogo PortMaster
A65: Perfect Dark | B65: Recomendados (PortMaster) | C65: Funciona | D65: PortMaster | E65: Tu ROM | F65: Control | H65: Catálogo PortMaster
...

Sheet Resumen
A3: Cantidad de juegos por sección y estado
A4: Se actualiza solo si cambiás la hoja Lista completa.
A6: Estado | B6: Tus juegos | C6: Recomendados (PortMaster) | D6: Emuladores de ArkOS | E6: Ola de ports de PS Vita 2024-26 | F6: Android | G6: Otros candidatos | H6: Fuera de alcance | I6: Total
A7: Funciona | B7: =COUNTIFS('Lista completa'!$B$4:$B$194,B$6,'Lista completa'!$C$4:$C$194,$A7) -> 25 | C7: =COUNTIFS('Lista completa'!$B$4:$B$194,C$6,'Lista completa'!$C$4:$C$194,$A7) -> 70 | D7: =COUNTIFS('Lista completa'!$B$4:$B$194,D$6,'Lista completa'!$C$4:$C$194,$A7) -> 21 | E7: =COUNTIFS('Lista completa'!$B$4:$B$194,E$6,'Lista completa'!$C$4:$C$194,$A7) -> 0 | F7: =COUNTIFS('Lista completa'!$B$4:$B$194,F$6,'Lista completa'!$C$4:$C$194,$A7) -> 7 | G7: =COUNTIFS('Lista completa'!$B$4:$B$194,G$6,'Lista completa'!$C$4:$C$194,$A7) -> 0 | H7: =COUNTIFS('Lista completa'!$B$4:$B$194,H$6,'Lista completa'!$C$4:$C$194,$A7) -> 0 | I7: =SUM(B7:H7) -> 123
A8: Con reservas | B8: =COUNTIFS('Lista completa'!$B$4:$B$194,B$6,'Lista completa'!$C$4:$C$194,$A8) -> 8 | C8: =COUNTIFS('Lista completa'!$B$4:$B$194,C$6,'Lista completa'!$C$4:$C$194,$A8) -> 1 | D8: =COUNTIFS('Lista completa'!$B$4:$B$194,D$6,'Lista completa'!$C$4:$C$194,$A8) -> 1 | E8: =COUNTIFS('Lista completa'!$B$4:$B$194,E$6,'Lista completa'!$C$4:$C$194,$A8) -> 0 | F8: =COUNTIFS('Lista completa'!$B$4:$B$194,F$6,'Lista completa'!$C$4:$C$194,$A8) -> 0 | G8: =COUNTIFS('Lista completa'!$B$4:$B$194,G$6,'Lista completa'!$C$4:$C$194,$A8) -> 0 | H8: =COUNTIFS('Lista completa'!$B$4:$B$194,H$6,'Lista completa'!$C$4:$C$194,$A8) -> 0 | I8: =SUM(B8:H8) -> 10
A9: Proyecto | B9: =COUNTIFS('Lista completa'!$B$4:$B$194,B$6,'Lista completa'!$C$4:$C$194,$A9) -> 3 | C9: =COUNTIFS('Lista completa'!$B$4:$B$194,C$6,'Lista completa'!$C$4:$C$194,$A9) -> 0 | D9: =COUNTIFS('Lista completa'!$B$4:$B$194,D$6,'Lista completa'!$C$4:$C$194,$A9) -> 0 | E9: =COUNTIFS('Lista completa'!$B$4:$B$194,E$6,'Lista completa'!$C$4:$C$194,$A9) -> 7 | F9: =COUNTIFS('Lista completa'!$B$4:$B$194,F$6,'Lista completa'!$C$4:$C$194,$A9) -> 13 | G9: =COUNTIFS('Lista completa'!$B$4:$B$194,G$6,'Lista completa'!$C$4:$C$194,$A9) -> 8 | H9: =COUNTIFS('Lista completa'!$B$4:$B$194,H$6,'Lista completa'!$C$4:$C$194,$A9) -> 0 | I9: =SUM(B9:H9) -> 31
A10: No (streaming) | B10: =COUNTIFS('Lista completa'!$B$4:$B$194,B$6,'Lista completa'!$C$4:$C$194,$A10) -> 18 | C10: =COUNTIFS('Lista completa'!$B$4:$B$194,C$6,'Lista completa'!$C$4:$C$194,$A10) -> 0 | D10: =COUNTIFS('Lista completa'!$B$4:$B$194,D$6,'Lista completa'!$C$4:$C$194,$A10) -> 0 | E10: =COUNTIFS('Lista completa'!$B$4:$B$194,E$6,'Lista completa'!$C$4:$C$194,$A10) -> 0 | F10: =COUNTIFS('Lista completa'!$B$4:$B$194,F$6,'Lista completa'!$C$4:$C$194,$A10) -> 0 | G10: =COUNTIFS('Lista completa'!$B$4:$B$194,G$6,'Lista completa'!$C$4:$C$194,$A10) -> 0 | H10: =COUNTIFS('Lista completa'!$B$4:$B$194,H$6,'Lista completa'!$C$4:$C$194,$A10) -> 9 | I10: =SUM(B10:H10) -> 27
A11: Total | B11: =SUM(B7:B10) -> 54 | C11: =SUM(C7:C10) -> 71 | D11: =SUM(D7:D10) -> 22 | E11: =SUM(E7:E10) -> 7 | F11: =SUM(F7:F10) -> 20 | G11: =SUM(G7:G10) -> 8 | H11: =SUM(H7:H10) -> 9 | I11: =SUM(I7:I10) -> 191
A13: Control: filas de la lista | B13: =COUNTA('Lista completa'!$A$4:$A$194) -> 191

Sheet Para portear
A3: Orden | B3: Proyecto | C3: Esfuerzo | D3: Por qué conviene | E3: Qué hace falta
A4: 1 | B4: The Elder Scrolls: Arena como port | C4: Bajo | D4: Es gratis y es de PC: se arma como entrada del menú Ports con sus controles, igual que FF7 | E4: DOSBox empaquetado; motor nativo cuando OpenTESArena esté completo
A5: 2 | B5: Star Wars: KOTOR 1 y 2 | C5: Medio | D5: El cargador de Android ya existe en Vita (VitaKotor); KOTOR II va a ~25 FPS allá | E5: Llevar el cargador a Linux; tu APK
A6: 3 | B6: Juegos de Android ya portados a PS Vita (GTA III/VC/SA, BG: Dark Alliance, NFS Hot Pursuit, Mass Effect Infiltrator, Fahrenheit, Thimbleweed Park, Dead Space, Bully) | C6: Medio | D6: PortMaster ya hizo lo mismo con Max Payne y Layton | E6: Adaptar cada cargador a Linux; tu APK
A7: 4 | B7: Juegos de GameMaker sin port (UFO 50, Katana Zero, Momodora, Gunpoint, Heat Signature) | C7: Bajo a medio | D7: PortMaster ya tiene el cargador de GameMaker | E7: Que la versión de PC traiga data.win
A8: 5 | B8: Cassette Beasts / Salt and Sanctuary | C8: Medio | D8: PortMaster ya tiene los motores (Godot 3 y Mono/FNA) | E8: Tus archivos; verificar la RAM
A9: 6 | B9: Minecraft: Bedrock | C9: Medio | D9: El lanzador para Linux ARM64 ya existe | E9: Tu APK; con 1 GB es dudoso
A10: 7 | B10: Cuphead | C10: Alto | D10: Ya existe una reimplementación parcial en Vita | E10: Revisar si su código está publicado y cuánto depende de la Vita
A11: 8 | B11: Resident Evil 4 (GameCube) | C11: Alto | D11: GameCube no se puede emular en la R36S; si el port de Vita avanza, es candidato | E11: Esperar a que el port de Vita avance
A12: 9 | B12: Vampire Survivors | C12: Alto | D12: El código se puede leer; el límite es la potencia | E12: Motor nuevo hecho a medida

Sheet Leyenda
A3: Término | B3: Significado
A4: R36S | B4: 4 núcleos ARM Cortex-A35 a ~1,5 GHz, GPU Mali-G31 (OpenGL ES), 1 GB de RAM, pantalla de 640×480, dos sticks.
A5: Funciona | B5: Corre bien según el catálogo de PortMaster o por la época del juego.
A6: Con reservas | B6: Corre, pero puede ir lento o tener límites.
A7: Proyecto | B7: No existe todavía para la R36S, pero hay un camino concreto para hacerlo.
A8: No (streaming) | B8: No entra en la consola. Se juega con Moonlight: el juego corre en tu PC (Sunshine) y la R36S muestra la imagen. Necesita adaptador Wi-Fi USB.
A9: Stick como mouse | B9: Juegos pensados para mouse: el stick mueve el puntero. Cómodo en juegos por turnos, incómodo en tiempo real.
A10: Teclas mapeadas al control | B10: Juegos de DOS que usan teclado: se asignan teclas a los botones.
A11: Catálogo PortMaster | B11: Dato del catálogo oficial de PortMaster (octubre 2026): el port existe y no está marcado como exigente (equipo potente, 2 GB de RAM u OpenGL de PC).
A12: Estimación | B12: Juicio propio según el motor, la época y los requisitos del juego. No probado.
A13: Port en PS Vita | B13: Ya existe un port del juego para PS Vita. La Vita tiene 4 núcleos ARM a 333-444 MHz y 512 MB de RAM: la R36S la supera en procesador y RAM, con gráficos de potencia parecida. Cada port de Vita hay que adaptarlo a Linux (gráficos, controles, sonido).
A14: Ola de ports de PS Vita 2024-26 | B14: Ports recientes a PS Vita de juegos que no se pueden emular en la R36S (cargadores de Android, GameCube). Son candidatos fuertes.
... A41: Fuente | B41: GemRB y Baldur's Gate II EE: https://www.gamingonlinux.com/2026/03/infinity-engine-open-source-remake-gemrb-0-9-5-gets-baldurs-gate-ii-enhanced-edition-playable/
